<?xml version="1.0" encoding="UTF-8"?>
<testsuite name="Default test"
           tests="6"
           failures="4"
           errors="0"
           skipped="0"
           time="16.178">
  <properties />
            <testcase name="testRecord_server_name" time="0.041" classname="smoke.b.qccr.VerificationRecords_NormalTest">
                <failure type="java.lang.IndexOutOfBoundsException"
                  message="Index: 0, Size: 0"
              >
<![CDATA[java.lang.IndexOutOfBoundsException: Index: 0, Size: 0
  java.util.ArrayList.rangeCheck(Unknown Source)
  java.util.ArrayList.get(Unknown Source)
  smoke.b.qccr.VerificationRecords_NormalTest.testRecord_server_name(VerificationRecords_NormalTest.java:55)
  sun.reflect.NativeMethodAccessorImpl.invoke0(Native Method)
  sun.reflect.NativeMethodAccessorImpl.invoke(Unknown Source)
  sun.reflect.DelegatingMethodAccessorImpl.invoke(Unknown Source)
  java.lang.reflect.Method.invoke(Unknown Source)
  org.testng.internal.MethodInvocationHelper.invokeMethod(MethodInvocationHelper.java:84)
  org.testng.internal.Invoker.invokeMethod(Invoker.java:714)
  org.testng.internal.Invoker.invokeTestMethod(Invoker.java:901)
  org.testng.internal.Invoker.invokeTestMethods(Invoker.java:1231)
  org.testng.internal.TestMethodWorker.invokeTestMethods(TestMethodWorker.java:127)
  org.testng.internal.TestMethodWorker.run(TestMethodWorker.java:111)
  org.testng.TestRunner.privateRun(TestRunner.java:767)
  org.testng.TestRunner.run(TestRunner.java:617)
  org.testng.SuiteRunner.runTest(SuiteRunner.java:334)
  org.testng.SuiteRunner.runSequentially(SuiteRunner.java:329)
  org.testng.SuiteRunner.privateRun(SuiteRunner.java:291)
  org.testng.SuiteRunner.run(SuiteRunner.java:240)
  org.testng.SuiteRunnerWorker.runSuite(SuiteRunnerWorker.java:52)
  org.testng.SuiteRunnerWorker.run(SuiteRunnerWorker.java:86)
  org.testng.TestNG.runSuitesSequentially(TestNG.java:1224)
  org.testng.TestNG.runSuitesLocally(TestNG.java:1149)
  org.testng.TestNG.run(TestNG.java:1057)
  org.testng.remote.AbstractRemoteTestNG.run(AbstractRemoteTestNG.java:126)
  org.testng.remote.RemoteTestNG.initAndRun(RemoteTestNG.java:137)
  org.testng.remote.RemoteTestNG.main(RemoteTestNG.java:58)
]]>
      </failure>

          </testcase>
            <testcase name="testCountNum" time="12.061" classname="smoke.b.qccr.VerificationRecords_NormalTest">
                <failure type="java.lang.AssertionError"
                  message="数量不一致 expected [13] but found [0]"
              >
<![CDATA[java.lang.AssertionError: 数量不一致 expected [13] but found [0]
  org.testng.Assert.fail(Assert.java:94)
  org.testng.Assert.failNotEquals(Assert.java:494)
  org.testng.Assert.assertEquals(Assert.java:123)
  org.testng.Assert.assertEquals(Assert.java:176)
  com.common.ats.Assert.AtsAssertUtils.assertEquals(AtsAssertUtils.java:33)
  smoke.b.qccr.VerificationRecords_NormalTest.testCountNum(VerificationRecords_NormalTest.java:100)
  sun.reflect.NativeMethodAccessorImpl.invoke0(Native Method)
  sun.reflect.NativeMethodAccessorImpl.invoke(Unknown Source)
  sun.reflect.DelegatingMethodAccessorImpl.invoke(Unknown Source)
  java.lang.reflect.Method.invoke(Unknown Source)
  org.testng.internal.MethodInvocationHelper.invokeMethod(MethodInvocationHelper.java:84)
  org.testng.internal.Invoker.invokeMethod(Invoker.java:714)
  org.testng.internal.Invoker.invokeTestMethod(Invoker.java:901)
  org.testng.internal.Invoker.invokeTestMethods(Invoker.java:1231)
  org.testng.internal.TestMethodWorker.invokeTestMethods(TestMethodWorker.java:127)
  org.testng.internal.TestMethodWorker.run(TestMethodWorker.java:111)
  org.testng.TestRunner.privateRun(TestRunner.java:767)
  org.testng.TestRunner.run(TestRunner.java:617)
  org.testng.SuiteRunner.runTest(SuiteRunner.java:334)
  org.testng.SuiteRunner.runSequentially(SuiteRunner.java:329)
  org.testng.SuiteRunner.privateRun(SuiteRunner.java:291)
  org.testng.SuiteRunner.run(SuiteRunner.java:240)
  org.testng.SuiteRunnerWorker.runSuite(SuiteRunnerWorker.java:52)
  org.testng.SuiteRunnerWorker.run(SuiteRunnerWorker.java:86)
  org.testng.TestNG.runSuitesSequentially(TestNG.java:1224)
  org.testng.TestNG.runSuitesLocally(TestNG.java:1149)
  org.testng.TestNG.run(TestNG.java:1057)
  org.testng.remote.AbstractRemoteTestNG.run(AbstractRemoteTestNG.java:126)
  org.testng.remote.RemoteTestNG.initAndRun(RemoteTestNG.java:137)
  org.testng.remote.RemoteTestNG.main(RemoteTestNG.java:58)
]]>
      </failure>

          </testcase>
            <testcase name="testRecord_no" time="2.088" classname="smoke.b.qccr.VerificationRecords_NormalTest">
                <failure type="java.lang.IndexOutOfBoundsException"
                  message="Index: 0, Size: 0"
              >
<![CDATA[java.lang.IndexOutOfBoundsException: Index: 0, Size: 0
  java.util.ArrayList.rangeCheck(Unknown Source)
  java.util.ArrayList.get(Unknown Source)
  smoke.b.qccr.VerificationRecords_NormalTest.testRecord_no(VerificationRecords_NormalTest.java:44)
  sun.reflect.NativeMethodAccessorImpl.invoke0(Native Method)
  sun.reflect.NativeMethodAccessorImpl.invoke(Unknown Source)
  sun.reflect.DelegatingMethodAccessorImpl.invoke(Unknown Source)
  java.lang.reflect.Method.invoke(Unknown Source)
  org.testng.internal.MethodInvocationHelper.invokeMethod(MethodInvocationHelper.java:84)
  org.testng.internal.Invoker.invokeMethod(Invoker.java:714)
  org.testng.internal.Invoker.invokeTestMethod(Invoker.java:901)
  org.testng.internal.Invoker.invokeTestMethods(Invoker.java:1231)
  org.testng.internal.TestMethodWorker.invokeTestMethods(TestMethodWorker.java:127)
  org.testng.internal.TestMethodWorker.run(TestMethodWorker.java:111)
  org.testng.TestRunner.privateRun(TestRunner.java:767)
  org.testng.TestRunner.run(TestRunner.java:617)
  org.testng.SuiteRunner.runTest(SuiteRunner.java:334)
  org.testng.SuiteRunner.runSequentially(SuiteRunner.java:329)
  org.testng.SuiteRunner.privateRun(SuiteRunner.java:291)
  org.testng.SuiteRunner.run(SuiteRunner.java:240)
  org.testng.SuiteRunnerWorker.runSuite(SuiteRunnerWorker.java:52)
  org.testng.SuiteRunnerWorker.run(SuiteRunnerWorker.java:86)
  org.testng.TestNG.runSuitesSequentially(TestNG.java:1224)
  org.testng.TestNG.runSuitesLocally(TestNG.java:1149)
  org.testng.TestNG.run(TestNG.java:1057)
  org.testng.remote.AbstractRemoteTestNG.run(AbstractRemoteTestNG.java:126)
  org.testng.remote.RemoteTestNG.initAndRun(RemoteTestNG.java:137)
  org.testng.remote.RemoteTestNG.main(RemoteTestNG.java:58)
]]>
      </failure>

          </testcase>
            <testcase name="testMonth" time="0.965" classname="smoke.b.qccr.VerificationRecords_NormalTest">
                <failure type="java.lang.AssertionError"
                  message="数量不一致 expected [11] but found [0]"
              >
<![CDATA[java.lang.AssertionError: 数量不一致 expected [11] but found [0]
  org.testng.Assert.fail(Assert.java:94)
  org.testng.Assert.failNotEquals(Assert.java:494)
  org.testng.Assert.assertEquals(Assert.java:123)
  org.testng.Assert.assertEquals(Assert.java:176)
  com.common.ats.Assert.AtsAssertUtils.assertEquals(AtsAssertUtils.java:33)
  smoke.b.qccr.VerificationRecords_NormalTest.testMonth(VerificationRecords_NormalTest.java:159)
  sun.reflect.NativeMethodAccessorImpl.invoke0(Native Method)
  sun.reflect.NativeMethodAccessorImpl.invoke(Unknown Source)
  sun.reflect.DelegatingMethodAccessorImpl.invoke(Unknown Source)
  java.lang.reflect.Method.invoke(Unknown Source)
  org.testng.internal.MethodInvocationHelper.invokeMethod(MethodInvocationHelper.java:84)
  org.testng.internal.Invoker.invokeMethod(Invoker.java:714)
  org.testng.internal.Invoker.invokeTestMethod(Invoker.java:901)
  org.testng.internal.Invoker.invokeTestMethods(Invoker.java:1231)
  org.testng.internal.TestMethodWorker.invokeTestMethods(TestMethodWorker.java:127)
  org.testng.internal.TestMethodWorker.run(TestMethodWorker.java:111)
  org.testng.TestRunner.privateRun(TestRunner.java:767)
  org.testng.TestRunner.run(TestRunner.java:617)
  org.testng.SuiteRunner.runTest(SuiteRunner.java:334)
  org.testng.SuiteRunner.runSequentially(SuiteRunner.java:329)
  org.testng.SuiteRunner.privateRun(SuiteRunner.java:291)
  org.testng.SuiteRunner.run(SuiteRunner.java:240)
  org.testng.SuiteRunnerWorker.runSuite(SuiteRunnerWorker.java:52)
  org.testng.SuiteRunnerWorker.run(SuiteRunnerWorker.java:86)
  org.testng.TestNG.runSuitesSequentially(TestNG.java:1224)
  org.testng.TestNG.runSuitesLocally(TestNG.java:1149)
  org.testng.TestNG.run(TestNG.java:1057)
  org.testng.remote.AbstractRemoteTestNG.run(AbstractRemoteTestNG.java:126)
  org.testng.remote.RemoteTestNG.initAndRun(RemoteTestNG.java:137)
  org.testng.remote.RemoteTestNG.main(RemoteTestNG.java:58)
]]>
      </failure>

          </testcase>
  
  
            <testcase name="testRecord_sprice" time="0.047" classname="smoke.b.qccr.VerificationRecords_NormalTest" />
                <testcase name="testToday" time="0.976" classname="smoke.b.qccr.VerificationRecords_NormalTest" />
      
</testsuite>
